<?xml version="1.0"?>
<robot name="kobuki_arm" xmlns:xacro="http://ros.org/wiki/xacro">
	<xacro:macro name="kobuki_arm" params="parent">
		<material name="blue">
		<color rgba="0 0 1 1"/>
		</material>
		<material name="red">
		<color rgba="1 0 0 1"/>
		</material>
		<material name="green">
		<color rgba="0 1 0 1"/>
		</material>
		<material name="black">
		<color rgba="0 0 0 1"/>
		</material>
		<material name="white">
		<color rgba="1 1 1 1"/>
		</material>


		<joint name="arm_base_joint" type="fixed">
		<origin xyz="0.065 0 0.089" rpy="0 0 0" />
		<parent link="${parent}"/>
		<child link="arm_base_link" />
		</joint>

		<link name="arm_base_link">
		<visual>
			<geometry>
			<cylinder length="0.05" radius="0.07"/>
			</geometry>
			<origin xyz="0.0 0.0 0.025"/>
			<material name="blue"/>
		</visual>
		<collision>
			<geometry>
			<cylinder length="0.05" radius="0.07"/>
			</geometry>
			<origin xyz="0.0 0.0 0.025"/>
			<material name="blue"/>
		</collision>
		</link>


		<joint name="joint_arm_0" type="revolute">
		<parent link="arm_base_link"/>
		<child link="arm_link_0"/>
		<origin xyz="0.0 0.0 0.05"/>
		<axis xyz="0 0 1"/>
		<limit effort="1000" lower="-3.14" upper="3.14" velocity="5"/>
		</joint>

		
		<link name="arm_link_0">
		<visual>
			<geometry>
			<box size="0.025 0.05 0.03"/>
			</geometry>
			<origin xyz="0.0 0.0 0.015"/>
			<material name="white"/>
		</visual>
		<collision>
			<geometry>
			<box size="0.025 0.05 0.03"/>
			</geometry>
			<origin xyz="0.0 0.0 0.015"/>
			<material name="white"/>
		</collision>
		</link>


		<joint name="arm_joint_1" type="revolute">
		<parent link="arm_link_0"/>
		<child link="arm_link_1"/>
		<origin xyz="0.0 0.0 0.03"/>
		<axis xyz="0 1 0"/>
		<limit effort="1000" lower="-1.17" upper="1.17" velocity="5"/>
		</joint>
		
		<link name="arm_link_1">
		<visual>
			<geometry>
			<box size="0.02 0.02 0.11"/>
			</geometry>
			<origin xyz="0.0 0.0 0.045"/>
			<material name="black"/>
		</visual>
		<visual>
			<geometry>
			<box size="0.05 0.02 0.02"/>
			</geometry>
			<origin xyz="0.015 0.0 0.09"/>
			<material name="black"/>
		</visual>
		<collision>
			<geometry>
			<box size="0.02 0.02 0.11"/>
			</geometry>
			<origin xyz="0.0 0.0 0.045"/>
			<material name="black"/>
		</collision>
		<collision>
			<geometry>
			<box size="0.05 0.02 0.02"/>
			</geometry>
			<origin xyz="0.015 0.0 0.09"/>
			<material name="black"/>
		</collision>
		</link>


		<joint name="arm_joint_2" type="revolute">
		<parent link="arm_link_1"/>
		<child link="arm_link_2"/>
		<origin xyz="0.03 0.0 0.09"/>
		<axis xyz="0 1 0"/>
		<limit effort="1000" lower="-3.14" upper="3.14" velocity="5"/>
		</joint>


		<link name="arm_link_2">
		<visual>
			<geometry>
			<box size="0.02 0.02 0.11"/>
			</geometry>
			<origin xyz="0.0 0.0 0.045"/>
			<material name="white"/>
		</visual>
		<collision>
			<geometry>
			<box size="0.02 0.02 0.11"/>
			</geometry>
			<origin xyz="0.0 0.0 0.045"/>
			<material name="white"/>
		</collision>
		</link>


		<joint name="arm_joint_3" type="revolute">
		<parent link="arm_link_2"/>
		<child link="arm_link_3"/>
		<origin xyz="0.0 0.0 0.09"/>
		<axis xyz="0 1 0"/>
		<limit effort="1000" lower="-3.14" upper="3.14" velocity="5"/>
		</joint>

		<link name="arm_link_3">
		<visual>
			<geometry>
			<box size="0.02 0.02 0.13"/>
			</geometry>
			<origin xyz="0.0 0.0 0.055"/>
			<material name="red"/>
		</visual>
		<collision>
			<geometry>
			<box size="0.02 0.02 0.13"/>
			</geometry>
			<origin xyz="0.0 0.0 0.08"/>
		</collision>
		</link>


		<joint name="arm_joint_4" type="fixed">
		<parent link="arm_link_3"/>
		<child link="arm_link_4"/>
		<origin xyz="0.0 0.0 0.13"/>
		<axis xyz="0 0 1"/>
		</joint>

		<link name="arm_link_4">
		<visual>
			<geometry>
			<box size="0.02 0.02 0.02"/>
			</geometry>
			<origin xyz="0.0 0.0 0.0"/>
			<material name="green"/>
		</visual>
		<collision>
			<geometry>
			<box size="0.02 0.02 0.02"/>
			</geometry>
			<origin xyz="0.0 0.0 0.05"/>
		</collision>
		</link> 
		
		<joint name="arm_joint_L" type="prismatic">
		<parent link="arm_link_4"/>
		<child link="arm_link_L"/>
		<origin xyz="0.0 0.005 0.0"/>
		<axis xyz="0 1 0"/>
		<limit effort="100" lower="0.0" upper="0.03" velocity="5"/>
		</joint>

		<link name="arm_link_L">
		<visual>
			<geometry>
			<box size="0.02 0.01 0.04"/>
			</geometry>
			<origin xyz="0.0 0.0 0.03"/>
			<material name="blue"/>
		</visual>
		<collision>
			<geometry>
			<box size="0.02 0.01 0.04"/>
			</geometry>
			<origin xyz="0.0 0.0 0.03"/>
		</collision>
		</link> 

		<joint name="arm_joint_R" type="prismatic">
		<parent link="arm_link_4"/>
		<child link="arm_link_R"/>
		<origin xyz="0.0 -0.005 0.0"/>
		<axis xyz="0 -1 0"/>
		<limit effort="100" lower="0.0" upper="0.03" velocity="5"/>
		</joint>

		<link name="arm_link_R">
		<visual>
			<geometry>
			<box size="0.02 0.01 0.04"/>
			</geometry>
			<origin xyz="0.0 0.0 0.03"/>
			<material name="blue"/>
		</visual>
		<collision>
			<geometry>
			<box size="0.02 0.01 0.04"/>
			</geometry>
			<origin xyz="0.0 0.0 0.03"/>
		</collision>
		</link> 

		<!---->

  	</xacro:macro>
</robot>
