<?xml version="1.0"?>
<robot name="RobotArm">

	<material name="blue">
		<color rgba="0 0 1 1"/>
	</material>
	<material name="red">
		<color rgba="1 0 0 1"/>
	</material>
	<material name="green">
		<color rgba="0 1 0 1"/>
	</material>
	<material name="black">
		<color rgba="0 0 0 1"/>
	</material>
	<material name="white">
		<color rgba="1 1 1 1"/>
	</material>

	<link name="base_link">
		<visual>
			<geometry>
				<cylinder length="0.08" radius="0.07"/>
			</geometry>
			<origin xyz="0.0 0.0 0.4"/>
			<material name="blue"/>
		</visual>
		<collision>
			<geometry>
				<cylinder length="0.1" radius="0.4"/>
			</geometry>
			<origin xyz="0.0 0.0 0.025"/>
			<material name="blue"/>
		</collision>
	</link>

	<joint name="joint_0" type="revolute">
		<parent link="base_link"/>
		<child link="link_0"/>
		<origin xyz="0.0 0.0 0.08"/>
		<axis xyz="0 0 1"/>
		<limit effort="1000" lower="-3.14" upper="3.14" velocity="5"/>
	</joint>

	
	<link name="link_0">
		<visual>
			<geometry>
				<box size="0.025 0.05 0.03"/>
			</geometry>
			<origin xyz="0.0 0.0 0.015"/>
			<material name="white"/>
		</visual>
		<collision>
			<geometry>
				<box size="0.025 0.05 0.03"/>
			</geometry>
			<origin xyz="0.0 0.0 0.015"/>
			<material name="white"/>
		</collision>
	</link>


	<joint name="joint_1" type="revolute">
		<parent link="link_0"/>
		<child link="link_1"/>
		<origin xyz="0.0 0.0 0.03"/>
		<axis xyz="0 1 0"/>
		<limit effort="1000" lower="-3.14" upper="3.14" velocity="5"/>
	</joint>

	
	<link name="link_1">
		<visual>
			<geometry>
				<box size="0.02 0.02 0.11"/>
			</geometry>
			<origin xyz="0.0 0.0 0.045"/>
			<material name="black"/>
		</visual>
		<visual>
			<geometry>
				<box size="0.05 0.02 0.02"/>
			</geometry>
			<origin xyz="0.015 0.0 0.09"/>
			<material name="black"/>
		</visual>
		<collision>
			<geometry>
				<box size="0.02 0.02 0.11"/>
			</geometry>
			<origin xyz="0.0 0.0 0.045"/>
			<material name="black"/>
		</collision>
		<collision>
			<geometry>
				<box size="0.05 0.02 0.02"/>
			</geometry>
			<origin xyz="0.015 0.0 0.09"/>
			<material name="black"/>
		</collision>
	</link>

	<joint name="joint_2" type="revolute">
		<parent link="link_1"/>
		<child link="link_2"/>
		<origin xyz="0.03 0.0 0.09"/>
		<axis xyz="0 1 0"/>
		<limit effort="1000" lower="-3.14" upper="3.14" velocity="5"/>
	</joint>


	<link name="link_2">
		<visual>
			<geometry>
				<box size="0.02 0.02 0.11"/>
			</geometry>
			<origin xyz="0.0 0.0 0.045"/>
			<material name="white"/>
		</visual>
		<collision>
			<geometry>
				<box size="0.02 0.02 0.11"/>
			</geometry>
			<origin xyz="0.0 0.0 0.045"/>
			<material name="white"/>
		</collision>
	</link>

	<joint name="joint_3" type="revolute">
		<parent link="link_2"/>
		<child link="link_3"/>
		<origin xyz="0.0 0.0 0.09"/>
		<axis xyz="0 1 0"/>
		<limit effort="1000" lower="-3.14" upper="3.14" velocity="5"/>
	</joint>

	<link name="link_3">
		<visual>
			<geometry>
				<box size="0.02 0.02 0.13"/>
			</geometry>
			<origin xyz="0.0 0.0 0.055"/>
			<material name="red"/>
		</visual>
		<collision>
			<geometry>
				<box size="0.02 0.02 0.13"/>
			</geometry>
			<origin xyz="0.0 0.0 0.08"/>
		</collision>
	</link>


	<joint name="joint_4" type="prismatic">
		<parent link="link_3"/>
		<child link="link_4"/>
		<origin xyz="0.0 0.0 0.11"/>
		<axis xyz="0 0 1"/>
		<limit effort="1000" lower="-0.10" upper="0.06" velocity="5"/>
	</joint>

	<link name="link_4">
		<visual>
			<geometry>
				<box size="0.02 0.02 0.02"/>
			</geometry>
			<origin xyz="0.0 0.0 0.0"/>
			<material name="green"/>
		</visual>
		<collision>
			<geometry>
				<box size="0.02 0.02 0.02"/>
			</geometry>
			<origin xyz="0.0 0.0 0.05"/>
		</collision>
	</link>

</robot>
